<?xml version="1.0" ?>
<robot name="/home/diogo/catkin_ws/src/robots/carbot/carbot_description/urdf/carbot.urdf" version="1.0">
  <link name="base_link">
    <visual>
      <geometry>
        <box size="0.2 0.1 0.05"/>
      </geometry>
    </visual>
    <collision>
      <geometry>
        <box size="0.2 0.1 0.05"/>
      </geometry>
    </collision>
  </link>
  <joint name="wheel4" type="continuous">
    <origin xyz="-0.05 -0.06 0.0" rpy="1.5708 0.0 0.0"/>
    <axis xyz="0.0 -4e-06 -1.0"/>
    <parent link="base_link"/>
    <child link="wheel4"/>
    <limit effort="10.0" lower="0" upper="0" velocity="10.0"/>
  </joint>
  <link name="wheel4">
    <visual>
      <geometry>
        <cylinder radius="0.04" length="0.02"/>
      </geometry>
    </visual>
    <collision>
      <geometry>
        <cylinder radius="0.04" length="0.02"/>
      </geometry>
    </collision>
  </link>
  <joint name="wheel3" type="continuous">
    <origin xyz="-0.05 0.06 0.0" rpy="1.5708 0.0 0.0"/>
    <axis xyz="0.0 -4e-06 -1.0"/>
    <parent link="base_link"/>
    <child link="wheel3"/>
    <limit effort="10.0" lower="0" upper="0" velocity="10.0"/>
  </joint>
  <link name="wheel3">
    <visual>
      <geometry>
        <cylinder radius="0.04" length="0.02"/>
      </geometry>
    </visual>
    <collision>
      <geometry>
        <cylinder radius="0.04" length="0.02"/>
      </geometry>
    </collision>
  </link>
  <joint name="wheel2" type="continuous">
    <origin xyz="0.05 -0.06 0.0" rpy="1.5708 0.0 0.0"/>
    <axis xyz="0.0 -4e-06 -1.0"/>
    <parent link="base_link"/>
    <child link="wheel2"/>
    <limit effort="10.0" lower="0" upper="0" velocity="10.0"/>
  </joint>
  <link name="wheel2">
    <visual>
      <geometry>
        <cylinder radius="0.04" length="0.02"/>
      </geometry>
    </visual>
    <collision>
      <geometry>
        <cylinder radius="0.04" length="0.02"/>
      </geometry>
    </collision>
  </link>
  <joint name="wheel1" type="continuous">
    <origin xyz="0.05 0.06 0.0" rpy="1.5708 0.0 0.0"/>
    <axis xyz="0.0 -4e-06 -1.0"/>
    <parent link="base_link"/>
    <child link="wheel1"/>
    <limit effort="10.0" lower="0" upper="0" velocity="10.0"/>
  </joint>
  <link name="wheel1">
    <visual>
      <geometry>
        <cylinder radius="0.04" length="0.02"/>
      </geometry>
    </visual>
    <collision>
      <geometry>
        <cylinder radius="0.04" length="0.02"/>
      </geometry>
    </collision>
  </link>
  <link name="ds_right"/>
  <joint name="base_link_ds_right_joint" type="fixed">
    <origin xyz="0.105087 -0.032507 0.0" rpy="0.0 0.0 -0.3"/>
    <parent link="base_link"/>
    <child link="ds_right"/>
  </joint>
  <link name="ds_left"/>
  <joint name="base_link_ds_left_joint" type="fixed">
    <origin xyz="0.105087 0.032507 0.0" rpy="0.0 0.0 0.3"/>
    <parent link="base_link"/>
    <child link="ds_left"/>
  </joint>
  <link name="accelerometer"/>
  <joint name="base_link_accelerometer_joint" type="fixed">
    <origin xyz="0.0062609983603613365 0.0062412830525937655 0.034674001004381415" rpy="0.00999999999999596 -0.009999999999995996 -0.00999999999999596"/>
    <parent link="base_link"/>
    <child link="accelerometer"/>
  </joint>
  <link name="gyroscope"/>
  <joint name="base_link_gyroscope_joint" type="fixed">
    <origin xyz="0.0 0.0 0.03" rpy="0.0 0.0 0.0"/>
    <parent link="base_link"/>
    <child link="gyroscope"/>
  </joint>
</robot>