#VRML_SIM R2023a utf8

EXTERNPROTO "https://raw.githubusercontent.com/cyberbotics/webots/R2023a/projects/objects/backgrounds/protos/TexturedBackground.proto"
EXTERNPROTO "https://raw.githubusercontent.com/cyberbotics/webots/R2023a/projects/objects/backgrounds/protos/TexturedBackgroundLight.proto"
EXTERNPROTO "https://raw.githubusercontent.com/cyberbotics/webots/R2023a/projects/objects/floors/protos/Floor.proto"

WorldInfo {
  basicTimeStep 4
  FPS 165
}
Viewpoint {
  orientation 0.09594699500568744 -0.10862285824368474 -0.9894418875388038 4.82559575478883
  position -0.348822655008188 -14.062463849883567 3.367580205225637
}
TexturedBackground {
}
TexturedBackgroundLight {
}
Floor {
}
DEF CARBOT Robot {
  translation -2.3 0.480011 0.04
  rotation 0 0 1 -5.307179586466759e-06
  children [
    DEF MAIN_CAR_BODY Solid {
      children [
        DEF BODY Shape {
          appearance PBRAppearance {
            baseColor 0.8 0 0
            metalness 0
          }
          geometry Box {
            size 0.2 0.1 0.02
          }
        }
      ]
      boundingObject USE BODY
      physics Physics {
      }
    }
    Robot {
      children [
        Accelerometer {
          translation 0 0 0.015
          children [
            Shape {
              appearance PBRAppearance {
                baseColor 0.333333 1 1
                metalness 0
              }
              geometry DEF IMU_GEOMETRY Box {
                size 0.01 0.01 0.01
              }
            }
          ]
          boundingObject USE IMU_GEOMETRY
          physics Physics {
          }
        }
        Gyro {
          translation 0 0 0.015
          children [
            Shape {
              appearance PBRAppearance {
                baseColor 0.333333 1 1
                metalness 0
              }
              geometry DEF GYRO_GEOMETRY Box {
                size 0.01 0.01 0.01
              }
            }
          ]
          boundingObject USE GYRO_GEOMETRY
          physics Physics {
          }
        }
      ]
      name "imu"
      physics Physics {
      }
      controller "ros"
      controllerArgs [
        "--clock"
        "--use-sim-time"
      ]
    }
    DistanceSensor {
      translation 0.105087 0.0325072 0
      rotation 0 0 1 0.3
      children [
        Shape {
          appearance PBRAppearance {
          }
          geometry DEF DIST_SENSOR_GEOMETRY Box {
            size 0.01 0.01 0.01
          }
        }
      ]
      name "ds_left"
      boundingObject USE DIST_SENSOR_GEOMETRY
      physics Physics {
      }
    }
    DistanceSensor {
      translation 0.105087 -0.0325072 0
      rotation 0 0 1 -0.3
      children [
        Shape {
          appearance PBRAppearance {
          }
          geometry USE DIST_SENSOR_GEOMETRY
        }
      ]
      name "ds_right"
      boundingObject USE DIST_SENSOR_GEOMETRY
      physics Physics {
      }
    }
    HingeJoint {
      jointParameters HingeJointParameters {
        axis 0 1 0
        anchor 0.05 0.06 0
      }
      device [
        RotationalMotor {
          name "wheel1"
        }
      ]
      endPoint DEF WHEEL1 Solid {
        translation 0.05000000045014565 0.060000000274105014 5.408415775943068e-06
        rotation 1 3.366429293122923e-12 -3.2872650238836155e-12 1.5708000007939522
        children [
          DEF WHEEL Shape {
            appearance PBRAppearance {
              baseColor 0.133333 0.560784 0.00392157
              roughness 1
              metalness 0
            }
            geometry Cylinder {
              height 0.02
              radius 0.04
            }
          }
        ]
        name "wheel1"
        boundingObject USE WHEEL
        physics Physics {
        }
      }
    }
    HingeJoint {
      jointParameters HingeJointParameters {
        axis 0 1 0
        anchor 0.05 -0.06 0
      }
      device [
        RotationalMotor {
          name "wheel2"
        }
      ]
      endPoint Solid {
        translation 0.04999656604215935 -0.06000000008445555 1.959394277426722e-06
        rotation 0.999999999999439 -7.488923563815116e-07 7.490766169912509e-07 1.5707999999785165
        children [
          USE WHEEL
        ]
        name "wheel2"
        boundingObject USE WHEEL
        physics Physics {
        }
      }
    }
    HingeJoint {
      jointParameters HingeJointParameters {
        axis 0 1 0
        anchor -0.05 0.06 0
      }
      device [
        RotationalMotor {
          name "wheel3"
        }
      ]
      endPoint Solid {
        translation -0.050000000123442814 0.05999999995401828 5.055511932066952e-06
        rotation 1 -1.4321267775256102e-11 1.4324105141491362e-11 1.5708000000418674
        children [
          USE WHEEL
        ]
        name "wheel3"
        boundingObject USE WHEEL
        physics Physics {
        }
      }
    }
    HingeJoint {
      jointParameters HingeJointParameters {
        axis 0 1 0
        anchor -0.05 -0.06 0
      }
      device [
        RotationalMotor {
          name "wheel4"
        }
      ]
      endPoint Solid {
        translation -0.05000340770365371 -0.060000000083814065 1.9286145760965435e-06
        rotation 0.999999999999439 -7.489097984281092e-07 7.490936505005412e-07 1.5707999999784825
        children [
          USE WHEEL
        ]
        name "wheel4"
        boundingObject USE WHEEL
        physics Physics {
        }
      }
    }
  ]
  boundingObject DEF BODY Shape {
    appearance PBRAppearance {
      baseColor 1 0.0117647 0.0117647
      roughness 1
      metalness 0
    }
    geometry DEF BODY_GEOM Box {
      size 0.2 0.1 0.02
    }
  }
  physics Physics {
  }
  controller "plain_wheel_controller"
  supervisor TRUE
  synchronization FALSE
}
Robot {
  rotation 0 1 0 0
  name "supervisor_force_torque_applier"
  controller "<none>"
  supervisor TRUE
  synchronization FALSE
}
Robot {
  translation 0.1 0 0.1
  name "world_base_link_tf_pub"
  controller "world_base_link_tf_pub"
  supervisor TRUE
  synchronization FALSE
}
DEF WORLD_DUMMY Solid {
  name "world"
}
Solid {
  translation -1.12672 0 0.087972
  rotation 0 1 0 -0.1
  children [
    Shape {
      appearance PBRAppearance {
        baseColor 0.333333 0.341176 0.32549
        metalness 0
      }
      geometry DEF RAMP Plane {
        size 2 10
      }
    }
  ]
  name "ramp"
  boundingObject USE RAMP
}
