#VRML_SIM R2023a utf8

EXTERNPROTO "https://raw.githubusercontent.com/cyberbotics/webots/R2023a/projects/objects/backgrounds/protos/TexturedBackground.proto"
EXTERNPROTO "https://raw.githubusercontent.com/cyberbotics/webots/R2023a/projects/objects/backgrounds/protos/TexturedBackgroundLight.proto"
EXTERNPROTO "https://raw.githubusercontent.com/cyberbotics/webots/R2023a/projects/objects/floors/protos/Floor.proto"
EXTERNPROTO "https://raw.githubusercontent.com/cyberbotics/webots/R2023a/projects/objects/obstacles/protos/Ramp30deg.proto"

WorldInfo {
  basicTimeStep 8
  FPS 144
}
Viewpoint {
  orientation 0.1956252360405105 -0.21488341519540013 -0.9568468450583175 4.762140454464904
  position 0.10889276993800553 -4.581918028532758 2.2580622839455544
}
TexturedBackground {
}
TexturedBackgroundLight {
}
Floor {
}
Ramp30deg {
  translation 3.2 -2 0
  name "ramp 30 degrees(1)"
}
Ramp30deg {
  translation 3.2 2 0
  name "ramp 30 degrees(2)"
}
Ramp30deg {
  translation -2.96 0 0
  rotation 0 1 0 0
  name "ramp 30 degrees(3)"
}
Ramp30deg {
  translation -2.96 2 0
  rotation 0 1 0 0
  name "ramp 30 degrees(4)"
}
Ramp30deg {
  translation -2.96 -2 0
  rotation 0 1 0 0
  name "ramp 30 degrees(5)"
}
Ramp30deg {
  translation 3.2 0 0
}
DEF CARBOT Robot {
  translation 0 0.48 0.04
  children [
    Gyro {
      translation 0 0 0.015
      children [
        Shape {
          appearance PBRAppearance {
            baseColor 0.333333 1 1
            metalness 0
          }
          geometry DEF GYRO_GEOMETRY Box {
            size 0.01 0.01 0.01
          }
        }
      ]
      boundingObject USE GYRO_GEOMETRY
      physics Physics {
      }
    }
    Accelerometer {
      translation 0 0 0.015
      children [
        Shape {
          appearance PBRAppearance {
            baseColor 0.333333 1 1
            metalness 0
          }
          geometry DEF IMU_GEOMETRY Box {
            size 0.01 0.01 0.01
          }
        }
      ]
      boundingObject USE IMU_GEOMETRY
      physics Physics {
      }
    }
    DistanceSensor {
      translation 0.105087 0.0325072 0
      rotation 0 0 1 0.3
      children [
        Shape {
          appearance PBRAppearance {
          }
          geometry DEF DIST_SENSOR_GEOMETRY Box {
            size 0.01 0.01 0.01
          }
        }
      ]
      name "ds_left"
      boundingObject USE DIST_SENSOR_GEOMETRY
      physics Physics {
      }
    }
    DistanceSensor {
      translation 0.105087 -0.0325072 0
      rotation 0 0 1 -0.3
      children [
        Shape {
          appearance PBRAppearance {
          }
          geometry USE DIST_SENSOR_GEOMETRY
        }
      ]
      name "ds_right"
      boundingObject USE DIST_SENSOR_GEOMETRY
      physics Physics {
      }
    }
    DEF BODY Shape {
      appearance PBRAppearance {
        baseColor 1 0.0117647 0.0117647
        roughness 1
        metalness 0
      }
      geometry Box {
        size 0.2 0.1 0.02
      }
    }
    HingeJoint {
      jointParameters HingeJointParameters {
        axis 0 1 0
        anchor 0.05 0.06 0
      }
      device [
        RotationalMotor {
          name "wheel1"
        }
      ]
      endPoint DEF WHEEL1 Solid {
        translation 0.05 0.06 0
        rotation 1 0 0 1.5708
        children [
          DEF WHEEL Shape {
            appearance PBRAppearance {
              baseColor 0.133333 0.560784 0.00392157
              roughness 1
              metalness 0
            }
            geometry Cylinder {
              height 0.02
              radius 0.04
            }
          }
        ]
        name "wheel1"
        boundingObject USE WHEEL
        physics Physics {
        }
      }
    }
    HingeJoint {
      jointParameters HingeJointParameters {
        axis 0 1 0
        anchor 0.05 -0.06 0
      }
      device [
        RotationalMotor {
          name "wheel2"
        }
      ]
      endPoint Solid {
        translation 0.05 -0.06 0
        rotation 1 0 0 1.5708
        children [
          USE WHEEL
        ]
        name "wheel2"
        boundingObject USE WHEEL
        physics Physics {
        }
      }
    }
    HingeJoint {
      jointParameters HingeJointParameters {
        axis 0 1 0
        anchor -0.05 0.06 0
      }
      device [
        RotationalMotor {
          name "wheel3"
        }
      ]
      endPoint Solid {
        translation -0.05 0.06 0
        rotation 1 0 0 1.5708
        children [
          USE WHEEL
        ]
        name "wheel3"
        boundingObject USE WHEEL
        physics Physics {
        }
      }
    }
    HingeJoint {
      jointParameters HingeJointParameters {
        axis 0 1 0
        anchor -0.05 -0.06 0
      }
      device [
        RotationalMotor {
          name "wheel4"
        }
      ]
      endPoint Solid {
        translation -0.05 -0.06 0
        rotation 1 0 0 1.5708
        children [
          USE WHEEL
        ]
        name "wheel4"
        boundingObject USE WHEEL
        physics Physics {
        }
      }
    }
  ]
  boundingObject USE BODY
  physics Physics {
  }
  controller "ros"
  controllerArgs [
    "--use-sim-time"
    "--clock"
  ]
  synchronization FALSE
}
Robot {
  rotation 0 1 0 0
  name "supervisor_robot_control"
  controller "supervisor_robot_control"
  supervisor TRUE
  synchronization FALSE
}
Robot {
  translation 0.1 0 0.1
  name "world_base_link_tf_pub"
  controller "world_base_link_tf_pub"
  supervisor TRUE
  synchronization FALSE
}
DEF WORLD_DUMMY Solid {
  name "world"
}
