<?xml version="1.0"?>
<robot name="/home/diogo/catkin_ws/src/robots/carbot/carbot_description/urdf/carbot2.urdf" xmlns:xacro="http://ros.org/wiki/xacro">
  <link name="base_link">
    <visual>
      <geometry>
        <box size="0.2 0.1 0.02"/>
      </geometry>
    </visual>
    <collision>
      <geometry>
        <box size="0.2 0.1 0.02"/>
      </geometry>
    </collision>
  </link>
  <joint name="wheel4" type="continuous">
    <parent link="base_link"/>
    <child link="wheel4"/>
    <axis xyz="0 -0.000004 -1"/>
    <limit effort="10" velocity="10"/>
    <origin xyz="-0.05 -0.06 0" rpy="1.5708 -0.000001 0"/>
  </joint>
  <link name="wheel4">
    <visual>
      <origin xyz="-0.000003 0.000002 0" rpy="0 0 0"/>
      <geometry>
        <cylinder radius="0.04" length="0.02"/>
      </geometry>
    </visual>
    <collision>
      <origin xyz="-0.000003 0.000002 0" rpy="0 0 0"/>
      <geometry>
        <cylinder radius="0.04" length="0.02"/>
      </geometry>
    </collision>
  </link>
  <joint name="wheel3" type="continuous">
    <parent link="base_link"/>
    <child link="wheel3"/>
    <axis xyz="0 -0.000004 -1"/>
    <limit effort="10" velocity="10"/>
    <origin xyz="-0.050003 0.060002 0" rpy="1.5708 0 0"/>
  </joint>
  <link name="wheel3">
    <visual>
      <origin xyz="0 0.000005 0" rpy="0 0 0"/>
      <geometry>
        <cylinder radius="0.04" length="0.02"/>
      </geometry>
    </visual>
    <collision>
      <origin xyz="0 0.000005 0" rpy="0 0 0"/>
      <geometry>
        <cylinder radius="0.04" length="0.02"/>
      </geometry>
    </collision>
  </link>
  <joint name="wheel2" type="continuous">
    <parent link="base_link"/>
    <child link="wheel2"/>
    <axis xyz="0 -0.000004 -1"/>
    <limit effort="10" velocity="10"/>
    <origin xyz="0.05 -0.059995 0" rpy="1.5708 -0.000001 0"/>
  </joint>
  <link name="wheel2">
    <visual>
      <origin xyz="-0.000003 0.000002 0" rpy="0 0 0"/>
      <geometry>
        <cylinder radius="0.04" length="0.02"/>
      </geometry>
    </visual>
    <collision>
      <origin xyz="-0.000003 0.000002 0" rpy="0 0 0"/>
      <geometry>
        <cylinder radius="0.04" length="0.02"/>
      </geometry>
    </collision>
  </link>
  <joint name="wheel1" type="continuous">
    <parent link="base_link"/>
    <child link="wheel1"/>
    <axis xyz="0 -0.000004 -1"/>
    <limit effort="10" velocity="10"/>
    <origin xyz="0.049997 0.060002 0" rpy="1.5708 0 0"/>
  </joint>
  <link name="wheel1">
    <visual>
      <origin xyz="0 0.000005 0" rpy="0 0 0"/>
      <geometry>
        <cylinder radius="0.04" length="0.02"/>
      </geometry>
    </visual>
    <collision>
      <origin xyz="0 0.000005 0" rpy="0 0 0"/>
      <geometry>
        <cylinder radius="0.04" length="0.02"/>
      </geometry>
    </collision>
  </link>
  <link name="ds_right">
  </link>
  <joint name="base_link_ds_right_joint" type="fixed">
    <parent link="base_link"/>
    <child link="ds_right"/>
    <origin xyz="0.105087 -0.032502 0" rpy="0 0 -0.3"/>
  </joint>
  <link name="ds_left">
  </link>
  <joint name="base_link_ds_left_joint" type="fixed">
    <parent link="base_link"/>
    <child link="ds_left"/>
    <origin xyz="0.105087 0.032507 0" rpy="0 0 0.3"/>
  </joint>
  <!-- <link name="base_link"> -->
  <!-- </link> -->
  <link name="gyro">
  </link>
  <joint name="base_link_gyro_joint" type="fixed">
    <parent link="base_link"/>
    <child link="gyro"/>
    <origin xyz="0 0 0.015" rpy="0 0 0"/>
  </joint>
  <link name="accelerometer">
  </link>
  <joint name="base_link_accelerometer_joint" type="fixed">
    <parent link="base_link"/>
    <child link="accelerometer"/>
    <origin xyz="0 0 0.015" rpy="0 0 0"/>
  </joint>
  <link name="solid">
    <visual>
      <geometry>
        <box size="0.2 0.1 0.02"/>
      </geometry>
    </visual>
    <collision>
      <geometry>
        <box size="0.2 0.1 0.02"/>
      </geometry>
    </collision>
  </link>
  <joint name="base_link_solid_joint" type="fixed">
    <parent link="base_link"/>
    <child link="solid"/>
    <origin xyz="0 0 0" rpy="0 0 0"/>
  </joint>
</robot>
